<robot name="vehicle">

  <!-- ======= Body ======= -->
  <link name="vehicle_base_link" />
  <link name="body_link">
    <visual>
      <origin xyz="0.0 0.0 0.0"/>
      <geometry>
        <box size="0.55 0.42 0.26" /> <!--Actual Dim 0.82 0.42 0.26 -->
      </geometry>
      <material name="clearpath yellow">
	      <color rgba="1.0 0.75 0.15 1.0"/>
      </material>
    </visual> 
  </link>

  <joint name="base_body" type="fixed">
    <parent link="vehicle_base_link"/>
    <child link="body_link"/>
    <origin xyz="0.0 0.0 0.255" rpy="0.0 0.0 0.0" />
    <axis xyz="1.0 0.0 0.0" />
  </joint>

  <!-- ======= Bearing ======= -->
  <link name="bearing_link">
    <visual>
      <geometry>
        <cylinder radius="0.15" length=".1054" />
      </geometry>
      <material name="gray">
	      <color rgba=".2 .2 .2 1" />
      </material>
    </visual>
  </link>

  <joint name="body_to_bearing" type="continuous">
    <parent link="body_link"/>
    <child link="bearing_link"/>
    <origin xyz="0 0 .1827" rpy="0 0 0" /> <!--publish rotation-->
	<axis xyz="0 0 1" />
  </joint>

  <!-- ======= Arm ======= -->
  <link name="arm_upper_link">
    <visual>
      <geometry>
        <box size="0.3874 0.0762 0.0381" />
      </geometry>
      <material name="carbon">
	      <color rgba="0.15 0.15 0.15 1.0" />
      </material>
    </visual>
  </link>

  <link name="arm_lower_link">
    <visual>
      <geometry>
        <box size="0.3238 0.0762 0.0381" />
      </geometry>
      <material name="carbon">
	      <color rgba="0.15 0.15 0.15 1.0" />
      </material>
    </visual>
  </link>

  <joint name="arm_to_bearing" type="fixed">
    <parent link="bearing_link"/>
    <child link="arm_upper_link"/>
	<origin xyz="-0.1937 0.0 0.03365" rpy="0 0.0 0.0" />
  </joint>

  <joint name="arm_to_arm" type="fixed">
    <parent link="arm_upper_link"/>
    <child link="arm_lower_link"/>
	<origin xyz="-0.322 0.0 -0.12" rpy="0 -0.785398163 0" />
  </joint>

  <!-- ======= Spool ======= -->
  <link name="spool_link">
    <visual>
      <geometry>
        <cylinder radius="0.175" length=".09" />
      </geometry>
      <material name="carbon">
	      <color rgba="0.15 0.15 0.15 1.0" />
      </material>
    </visual>
  </link>

 <joint name="bearing_to_spool" type="continuous">
    <parent link="bearing_link"/>
    <child link="spool_link"/>
    <origin xyz="0 0 .0977" rpy="0 0 0" /> <!--publish rotation-->
	<axis xyz="0 0 1" />
  </joint>

  <!-- ======= Lidar Box ======= -->
  <link name="lidar_box_link">
    <visual>
      <geometry>
         <box size=".15 .15 .1" />
      </geometry>
      <material name="carbon">
	      <color  rgba=".2 .2 .2 1" />
      </material>
    </visual>
  </link>

 <joint name="box_to_spool" type="fixed">
    <parent link="spool_link"/>
    <child link="lidar_box_link"/>
    <origin xyz="0 0 0.095" rpy="0 0 0" />
  </joint>

  <!-- ======= Laser ======= -->
  <link name="laser">
    <visual>
      <geometry>
        <box size=".08 .08 .08" />
      </geometry>
      <material name="sick beige">
	      <color rgba=".99 .86 .64 1" />
      </material>
    </visual>
  </link>

  <joint name="spool_to_laser" type="fixed">
    <parent link="spool_link"/>
    <child link="laser"/>
    <origin xyz="0.04180 0 0.1924" rpy="3.14 -1.8326 0" /> 
    <!-- Old Config <origin xyz="0.06881 0 0.1148" rpy="3.14 -1.57 0" />-->
    <!-- New Calculated as (0.577+0.1508)−0.5354 == hieght to top spool + height of lidar above spool less current model height of the center of the spool object-->
  </joint>

  <!-- ======= Pulley ======= -->
  <link name="pulley_link">
    <visual>
      <geometry>
        <cylinder radius="0.03" length="0.0183" />
      </geometry>
      <material name="gray">
	      <color rgba=".2 .2 .2 1" />
      </material>
    </visual>
  </link>

  <joint name="arm_to_pulley" type="continuous">
    <parent link="arm_upper_link"/>
    <child link="pulley_link"/>
    <origin xyz="-0.0787 0 .05849" rpy="1.57 0 0" />
	<axis xyz="0 0 1" />
  </joint>

  <!-- ======= Pitch ======= -->
  <link name="pitch_link">
    <visual>
      <geometry>
        <cylinder radius="0.019" length="0.0762" />
      </geometry>
      <material name="gray">
	      <color rgba=".2 .2 .2 1" />
      </material>
    </visual>
  </link>

  <joint name="arm_to_pitch" type="continuous">
    <parent link="arm_lower_link"/>
    <child link="pitch_link"/>
    <origin xyz="-0.19 0 0" rpy="1.57 3.93 0" />
	<axis xyz="0 0 1" />
  </joint>

  <!-- ======= Camera / IMU ======= -->

  <link name="mount_link"> <!-- CAM0 expects base_link TF-->
    <visual>
      <geometry>
        <cylinder radius="0.019" length="0.03" />
      </geometry>
      <material name="gray">
	      <color rgba=".2 .2 .2 1" />
      </material>
    </visual>
  </link>

  <link name="cam0"> <!-- CAM0 is left camera (-x direction) -->
    <visual>
      <geometry>
        <box size="0.03 0.03 0.03" /> <!-- actual camera size<box size=".15 .082 .0423" /> -->
      </geometry>
      <material name="light blue">
	      <color rgba="0 1 1 1" />
      </material>
    </visual>
  </link>

  <link name="imu0">
    <visual>
      <geometry>
        <box size="0.03 0.03 0.03" /> <!-- actual camera size<box size=".15 .082 .0423" /> -->
      </geometry>
      <material name="purple">
	      <color rgba="0.64 0 1 1" />
      </material>
    </visual>
  </link>

  <joint name="mount_to_body" type="fixed">

    <!-- Adjust camera pitch 'p' (+ == down, - == up) -->

    <!-- Camera Mounted on front Robot Body (comment out if not used) -->
    <!--<parent link="body_link"/>
    <child link="mount_link"/>
    <origin xyz="-0.26 0 0.1533" rpy="1.57 0.18 3.14" />
	<axis xyz="0 0 1" />-->

    <!-- Camera Mounted on Arm/Bearing (comment out if not used) -->
    <parent link="bearing_link"/>
    <child link="mount_link"/>
    <origin xyz="-0.27 0 0.5596" rpy="1.57 0.36 0" />
	<axis xyz="0 0 1" />

  </joint>

  <joint name="camera_to_mount" type="fixed">
    <parent link="mount_link"/>
    <child link="cam0"/>
    <origin xyz="0.067 -0.011 0.055" rpy="0 1.57 0" /> <!-- Camera is flipped upside down ignore markings on circuit board -->
  </joint>

  <joint name="imu_to_camera" type="fixed">
    <parent link="cam0"/>
    <child link="imu0"/>
    <origin xyz="0.0479 -0.01698 0.02366" rpy="-3.14 3.14 0" /> 
    <!-- IMU pose is given by calibraion topic "camX/calibration, signs for position/orietation are reversed," -->
  </joint>

  <!-- ======= Wheels ======= -->
  <link name="front_left_wheel_link">
    <visual>
      <geometry>
	      <cylinder radius="0.165" length="0.125" />
      </geometry>
      <material name="gray">
	      <color rgba=".2 .2 .2 1" />
      </material>
    </visual>
  </link>

  <link name="front_right_wheel_link">
    <visual>
      <geometry>
	      <cylinder radius="0.165" length="0.125" />
      </geometry>
      <material name="gray"/>
    </visual>
  </link>

  <link name="rear_left_wheel_link">
    <visual>
      <geometry>
	      <cylinder radius="0.165" length="0.125" />
      </geometry>
      <material name="gray"/>
    </visual>
  </link>

  <link name="rear_right_wheel_link">
    <visual>
      <geometry>
	      <cylinder radius="0.165" length="0.125" />
      </geometry>
      <material name="gray"/>
    </visual>
  </link>

  <joint name="body_front_left_wheel" type="fixed">
    <parent link="body_link"/>
    <child link="front_left_wheel_link"/>
    <origin xyz="0.255 0.2825 -0.09" rpy="-1.57 0 0" />
  </joint>

  <joint name="body_front_right_wheel" type="fixed">
    <parent link="body_link"/>
    <child link="front_right_wheel_link"/>
    <origin xyz="0.255 -0.2825 -0.09" rpy="1.57 0 0" />
  </joint>

  <joint name="body_rear_left_wheel" type="fixed">
    <parent link="body_link"/>
    <child link="rear_left_wheel_link"/>
    <origin xyz="-0.255 0.2825 -0.09" rpy="-1.57 0 0" />
  </joint>

  <joint name="body_rear_right_wheel" type="fixed">
    <parent link="body_link"/>
    <child link="rear_right_wheel_link"/>
    <origin xyz="-0.255 -0.2825 -0.09" rpy="1.57 0 0" />
  </joint>

</robot>
